============================= test session starts ==============================
platform darwin -- Python 3.13.4, pytest-8.4.2, pluggy-1.6.0 -- /Users/sayedarizvi/starting-ragchatbot-codebase/.venv/bin/python3
cachedir: .pytest_cache
rootdir: /Users/sayedarizvi/starting-ragchatbot-codebase
configfile: pyproject.toml
plugins: mock-3.15.1, asyncio-1.2.0, anyio-4.9.0
asyncio: mode=Mode.STRICT, debug=False, asyncio_default_fixture_loop_scope=None, asyncio_default_test_loop_scope=function
collecting ... collected 47 items
INTERNALERROR> Traceback (most recent call last):
INTERNALERROR>   File "/Users/sayedarizvi/starting-ragchatbot-codebase/.venv/lib/python3.13/site-packages/_pytest/main.py", line 289, in wrap_session
INTERNALERROR>     session.exitstatus = doit(config, session) or 0
INTERNALERROR>                          ~~~~^^^^^^^^^^^^^^^^^
INTERNALERROR>   File "/Users/sayedarizvi/starting-ragchatbot-codebase/.venv/lib/python3.13/site-packages/_pytest/main.py", line 342, in _main
INTERNALERROR>     config.hook.pytest_collection(session=session)
INTERNALERROR>     ~~~~~~~~~~~~~~~~~~~~~~~~~~~~~^^^^^^^^^^^^^^^^^
INTERNALERROR>   File "/Users/sayedarizvi/starting-ragchatbot-codebase/.venv/lib/python3.13/site-packages/pluggy/_hooks.py", line 512, in __call__
INTERNALERROR>     return self._hookexec(self.name, self._hookimpls.copy(), kwargs, firstresult)
INTERNALERROR>            ~~~~~~~~~~~~~~^^^^^^^^^^^^^^^^^^^^^^^^^^^^^^^^^^^^^^^^^^^^^^^^^^^^^^^^
INTERNALERROR>   File "/Users/sayedarizvi/starting-ragchatbot-codebase/.venv/lib/python3.13/site-packages/pluggy/_manager.py", line 120, in _hookexec
INTERNALERROR>     return self._inner_hookexec(hook_name, methods, kwargs, firstresult)
INTERNALERROR>            ~~~~~~~~~~~~~~~~~~~~^^^^^^^^^^^^^^^^^^^^^^^^^^^^^^^^^^^^^^^^^
INTERNALERROR>   File "/Users/sayedarizvi/starting-ragchatbot-codebase/.venv/lib/python3.13/site-packages/pluggy/_callers.py", line 167, in _multicall
INTERNALERROR>     raise exception
INTERNALERROR>   File "/Users/sayedarizvi/starting-ragchatbot-codebase/.venv/lib/python3.13/site-packages/pluggy/_callers.py", line 139, in _multicall
INTERNALERROR>     teardown.throw(exception)
INTERNALERROR>     ~~~~~~~~~~~~~~^^^^^^^^^^^
INTERNALERROR>   File "/Users/sayedarizvi/starting-ragchatbot-codebase/.venv/lib/python3.13/site-packages/_pytest/logging.py", line 788, in pytest_collection
INTERNALERROR>     return (yield)
INTERNALERROR>             ^^^^^
INTERNALERROR>   File "/Users/sayedarizvi/starting-ragchatbot-codebase/.venv/lib/python3.13/site-packages/pluggy/_callers.py", line 139, in _multicall
INTERNALERROR>     teardown.throw(exception)
INTERNALERROR>     ~~~~~~~~~~~~~~^^^^^^^^^^^
INTERNALERROR>   File "/Users/sayedarizvi/starting-ragchatbot-codebase/.venv/lib/python3.13/site-packages/_pytest/warnings.py", line 99, in pytest_collection
INTERNALERROR>     return (yield)
INTERNALERROR>             ^^^^^
INTERNALERROR>   File "/Users/sayedarizvi/starting-ragchatbot-codebase/.venv/lib/python3.13/site-packages/pluggy/_callers.py", line 139, in _multicall
INTERNALERROR>     teardown.throw(exception)
INTERNALERROR>     ~~~~~~~~~~~~~~^^^^^^^^^^^
INTERNALERROR>   File "/Users/sayedarizvi/starting-ragchatbot-codebase/.venv/lib/python3.13/site-packages/_pytest/config/__init__.py", line 1450, in pytest_collection
INTERNALERROR>     return (yield)
INTERNALERROR>             ^^^^^
INTERNALERROR>   File "/Users/sayedarizvi/starting-ragchatbot-codebase/.venv/lib/python3.13/site-packages/pluggy/_callers.py", line 121, in _multicall
INTERNALERROR>     res = hook_impl.function(*args)
INTERNALERROR>   File "/Users/sayedarizvi/starting-ragchatbot-codebase/.venv/lib/python3.13/site-packages/_pytest/main.py", line 353, in pytest_collection
INTERNALERROR>     session.perform_collect()
INTERNALERROR>     ~~~~~~~~~~~~~~~~~~~~~~~^^
INTERNALERROR>   File "/Users/sayedarizvi/starting-ragchatbot-codebase/.venv/lib/python3.13/site-packages/_pytest/main.py", line 816, in perform_collect
INTERNALERROR>     hook.pytest_collection_modifyitems(
INTERNALERROR>     ~~~~~~~~~~~~~~~~~~~~~~~~~~~~~~~~~~^
INTERNALERROR>         session=self, config=self.config, items=items
INTERNALERROR>         ^^^^^^^^^^^^^^^^^^^^^^^^^^^^^^^^^^^^^^^^^^^^^
INTERNALERROR>     )
INTERNALERROR>     ^
INTERNALERROR>   File "/Users/sayedarizvi/starting-ragchatbot-codebase/.venv/lib/python3.13/site-packages/pluggy/_hooks.py", line 512, in __call__
INTERNALERROR>     return self._hookexec(self.name, self._hookimpls.copy(), kwargs, firstresult)
INTERNALERROR>            ~~~~~~~~~~~~~~^^^^^^^^^^^^^^^^^^^^^^^^^^^^^^^^^^^^^^^^^^^^^^^^^^^^^^^^
INTERNALERROR>   File "/Users/sayedarizvi/starting-ragchatbot-codebase/.venv/lib/python3.13/site-packages/pluggy/_manager.py", line 120, in _hookexec
INTERNALERROR>     return self._inner_hookexec(hook_name, methods, kwargs, firstresult)
INTERNALERROR>            ~~~~~~~~~~~~~~~~~~~~^^^^^^^^^^^^^^^^^^^^^^^^^^^^^^^^^^^^^^^^^
INTERNALERROR>   File "/Users/sayedarizvi/starting-ragchatbot-codebase/.venv/lib/python3.13/site-packages/pluggy/_callers.py", line 167, in _multicall
INTERNALERROR>     raise exception
INTERNALERROR>   File "/Users/sayedarizvi/starting-ragchatbot-codebase/.venv/lib/python3.13/site-packages/pluggy/_callers.py", line 139, in _multicall
INTERNALERROR>     teardown.throw(exception)
INTERNALERROR>     ~~~~~~~~~~~~~~^^^^^^^^^^^
INTERNALERROR>   File "/Users/sayedarizvi/starting-ragchatbot-codebase/.venv/lib/python3.13/site-packages/_pytest/cacheprovider.py", line 443, in pytest_collection_modifyitems
INTERNALERROR>     res = yield
INTERNALERROR>           ^^^^^
INTERNALERROR>   File "/Users/sayedarizvi/starting-ragchatbot-codebase/.venv/lib/python3.13/site-packages/pluggy/_callers.py", line 139, in _multicall
INTERNALERROR>     teardown.throw(exception)
INTERNALERROR>     ~~~~~~~~~~~~~~^^^^^^^^^^^
INTERNALERROR>   File "/Users/sayedarizvi/starting-ragchatbot-codebase/.venv/lib/python3.13/site-packages/_pytest/cacheprovider.py", line 373, in pytest_collection_modifyitems
INTERNALERROR>     res = yield
INTERNALERROR>           ^^^^^
INTERNALERROR>   File "/Users/sayedarizvi/starting-ragchatbot-codebase/.venv/lib/python3.13/site-packages/pluggy/_callers.py", line 121, in _multicall
INTERNALERROR>     res = hook_impl.function(*args)
INTERNALERROR>   File "/Users/sayedarizvi/starting-ragchatbot-codebase/backend/tests/conftest.py", line 86, in pytest_collection_modifyitems
INTERNALERROR>     if not config.ANTHROPIC_API_KEY:
INTERNALERROR>            ^^^^^^^^^^^^^^^^^^^^^^^^
INTERNALERROR> AttributeError: 'Config' object has no attribute 'ANTHROPIC_API_KEY'

============================ no tests ran in 0.04s =============================
